<mujoco>
  <option timestep="0.01" integrator="RK4" />
  <worldbody>
    <light pos="0 0 1.5" dir="0 0 -1" directional="true" />
    <geom name="floor" size="0 0 0.05" type="plane" material="groundplane" friction=".5 0.005 0.001"
      priority="2" condim="4" />
  </worldbody>

  <worldbody>

    <body name="ball" pos=".0 0 .05">
      <geom name="gball_0" type="sphere" size="0.02" mass="5." material="BallMat"
        friction=".5 0.005 0.001 " condim="4" />
      <site name="sensor_ball" />
      <joint name="joint_x" type="slide" pos="0 0 0" axis="1 0 0" />
      <joint name="joint_y" type="slide" pos="0 0 0" axis="0 1 0" />
      <joint name="joint_z" type="slide" pos="0 0 0" axis="0 0 1"
        limited="true" range="0 0.15" damping="60" />
    </body>


    <body name="wall_3" pos="0.5 0.0 .05">
      <geom name="wall_3" type="box" size="0.1 0.15 0.05" mass=".1" material="static" condim="4" />
    </body>

    <body name="case" pos="0 0 0.1">
      <geom name="gcase_a" type="box" size="0.05 0.32 0.1" pos="-.2 0 0" />
      <geom name="gcase_b" type="box" size="0.05 0.32 0.1" pos="1.1 0 0" />
      <geom name="gcase_c" type="box" size="0.7 0.04 0.1" pos="0.45 .36 0" />
      <geom name="gcase_d" type="box" size="0.7 0.04 0.1" pos="0.45 -.36 0" />
    </body>
    
    <!-- Translucent tank volume; forces are supplied by lib/fluid.py. -->
    <body name="water" pos="0.45 0 0.075">
      <!-- Filled from the floor to z=0.15: above wall_3, below the case walls. -->
      <geom name="water_surface" type="box" size="0.67 0.32 0.075"
        rgba="0.2 0.5 0.8 0.3" contype="0" conaffinity="0" />
    </body>
    <site name="underwater_target" type="sphere" pos="0.9 -0.22 0.06"
      size="0.035" rgba="0.1 1 1 0.8" />


  </worldbody>

  <actuator>
    <motor name="actuator_x" joint="joint_x" gear="15" ctrllimited="true" ctrlrange="-1 1" />
    <motor name="actuator_y" joint="joint_y" gear="15" ctrllimited="true" ctrlrange="-1 1" />
    <motor name="actuator_z" joint="joint_z" gear="80" ctrllimited="true" ctrlrange="-1 1" />
  </actuator>

  <asset>
    <!-- Materials for visualization -->
    <material name="MatPlane" rgba="0.8 0.9 0.8 1" />
    <material name="movable" rgba="0.94 1.0 0.0 1" />
    <material name="static" rgba="0.8 0.2 0.2 1" />
    <material name="BallMat" rgba="0.2 0.2 0.8 1" />

    <texture type="skybox" builtin="gradient" rgb1="0.3 0.5 0.7" rgb2="0 0 0" width="512" height="3072" />
    <texture type="2d" name="groundplane" builtin="checker" mark="edge" rgb1="0.2 0.3 0.4"
      rgb2="0.1 0.2 0.3"
      markrgb="0.8 0.8 0.8" width="300" height="300" />
    <material name="groundplane" texture="groundplane" texuniform="true" texrepeat="5 5"
      reflectance="0.2" />
  </asset>

  <visual>
    <headlight diffuse="0.6 0.6 0.6" ambient="0.3 0.3 0.3" specular="0 0 0" />
    <rgba haze="0.15 0.25 0.35 1" />
    <global azimuth="60" elevation="-20" />
  </visual>

  <sensor>
    <velocimeter name="sensor_ball" site="sensor_ball" />
  </sensor>

</mujoco>
